Workbook

Sheet Datos de Entrada (1)
A1: DATOS DE ENTRADA
A3: Programa Maestro de Producción (PMP)
B5: SEMANA
A6: PRODUCTO | B6: 17 | C6: 18 | D6: 19 | E6: 20
A7: P1 | B7: 100 | C7: 80 | D7: 100 | E7: 120 | F7: Producto final
A8: P2 | B8: 200 | C8: 200 | D8: 200 | E8: 250 | F8: Producto final
A9: C3 | B9: 0 | C9: 100 | D9: 100 | E9: 0 | F9: Pieza de repuesto de P1, P2
A10: C5 | B10: 50 | C10: 25 | D10: 100 | E10: 10 | F10: Pieza de repuesto de P2
A12: El Programa Maestro de Producción (PMP) es la estimación propia de productos o pedidos comprometidos (la demanda firme).
A13: Los Tiempos de Suministro (TS) son un dato fijo y establece las fechas de emisión y recepción de pedidos.
A15: Registro de Inventario: fichero de stocks y dinámica de pedidos
A17: Producto/Componente | B17: Stock de Seguridad (SS) | C17: Tiempo de suministro | D17: Defectos (%) | E17: Existencias disponibles | F17: Lote pedido
A18: P1 | B18: 50 | C18: 1 | D18: 0 | E18: 70 | F18: 1
A19: P2 | B19: 100 | C19: 1 | D19: 0 | E19: 120 | F19: 1
A20: S11 | B20: 0 | C20: 2 | D20: 0 | E20: 20 | F20: 100
A21: S12 | B21: 30 | C21: 2 | D21: 5 | E21: 20 | F21: 50
A22: S13 | B22: 0 | C22: 1 | D22: 10 | E22: 50 | F22: 75
A23: C1 | B23: 100 | C23: 1 | D23: 10 | E23: 50 | F23: 4
A24: C2 | B24: 100 | C24: 2 | D24: 10 | E24: 50 | F24: 12
A25: C3 | B25: 50 | C25: 1 | D25: 5 | E25: 150 | F25: 100
A26: C4 | B26: 75 | C26: 1 | D26: 15 | E26: 100 | F26: 75
A27: C5 | B27: 50 | C27: 2 | D27: 5 | E27: 10 | F27: 15
A29: El stock de seguridad (SS) del que debemos disponer.
A30: El tiempo de suministro en el que podemos contar con ellos, desde que se lanza su pedido a proveedores o su orden de trabajo (OT) a planta.
A31: El % de defectuosos que recibimos o fabricamos y deben ser desestimados a nivel productivo y/o comercial.
A32: Las existencias disponibles al lanzamiento del Plan, es decir, en el momento que se necesitan.
A33: El lote pedido establece el lote de uds. que configura el pedido, es decir, debemos elaborar pedidos u orden de trabajo (OT) que sean múltiplos de dichas cantidades.
A35: PRINCIPIO BASE
A37: Demanda de componentes discreta y discontinua: los productos se fabrican por lotes, y a medida que dicho lote avanza en su fabricación, se demandan sus componentes en momentos y cantidades concretas.
A38: El cumplimiento del PMP y la llegada de las compras, hace que se actualice el Registro de Inventario y el propio PMP.

Sheet Datos de Entrada (2)
A2: NIVEL 1 | H2: P1
A5: NIVEL 2 | F5: S11 | G5: 1
A8: NIVEL 3 | D8: C1 | E8: 1 | G8: C4 | H8: 2 | J8: C3 | K8: 1
A15: NIVEL 1 | H15: P2
A18: NIVEL 2 | C18: S12 | D18: 2 | G18: S13 | H18: 1
A21: NIVEL 3 | E21: C3 | F21: 3 | H21: C4 | I21: 2 | K21: C2 | L21: 1
A24: NIVEL 4 | C24: C5 | D24: 2 | H24: C5 | I24: 1

Sheet LANZ PP
A1: Informe de Explosión de Necesidades de un sistema MRP-I
A2: Planificación de Necesidades de Materiales (MRP) (LANZ PP)
B4: HOY
B5: LANZ PP | R5: SEMANA
A6: PRODUCTO | B6: 1 | C6: 2 | D6: 3 | E6: 4 | F6: 5 | G6: 6 | H6: 7 | I6: 8 | J6: 9 | K6: 10 | L6: 11 | M6: 12 | N6: 13 | O6: 14 | P6: 15 | Q6: 16 | R6: 17 | S6: 18 | T6: 19 | U6: 20
A7: P1 | B7: =B25 -> 0 | C7: =C25 -> 0 | D7: =D25 -> 0 | E7: =E25 -> 0 | F7: =F25 -> 0 | G7: =G25 -> 0 | H7: =H25 -> 0 | I7: =I25 -> 0 | ... U7: =U25 -> 0
A8: P2 | B8: =B34 -> 0 | C8: =C34 -> 0 | D8: =D34 -> 0 | E8: =E34 -> 0 | F8: =F34 -> 0 | G8: =G34 -> 0 | H8: =H34 -> 0 | I8: =I34 -> 0 | ... U8: =U34 -> 0
A9: S11 | B9: =B43 -> 0 | C9: =C43 -> 0 | D9: =D43 -> 0 | E9: =E43 -> 0 | F9: =F43 -> 0 | G9: =G43 -> 0 | H9: =H43 -> 0 | I9: =I43 -> 0 | ... U9: =U43 -> 0
A10: S12 | B10: =B52 -> 0 | C10: =C52 -> 0 | D10: =D52 -> 0 | E10: =E52 -> 0 | F10: =F52 -> 0 | G10: =G52 -> 0 | H10: =H52 -> 0 | I10: =I52 -> 0 | ... U10: =U52 -> 0
A11: S13 | B11: =B61 -> 0 | C11: =C61 -> 0 | D11: =D61 -> 0 | E11: =E61 -> 0 | F11: =F61 -> 0 | G11: =G61 -> 0 | H11: =H61 -> 0 | I11: =I61 -> 0 | ... U11: =U61 -> 0
A12: C1 | B12: =B70 -> 0 | C12: =C70 -> 0 | D12: =D70 -> 0 | E12: =E70 -> 0 | F12: =F70 -> 0 | G12: =G70 -> 0 | H12: =H70 -> 0 | I12: =I70 -> 0 | ... U12: =U70 -> 0
A13: C2 | B13: =B79 -> 0 | C13: =C79 -> 0 | D13: =D79 -> 0 | E13: =E79 -> 0 | F13: =F79 -> 0 | G13: =G79 -> 0 | H13: =H79 -> 0 | I13: =I79 -> 0 | ... U13: =U79 -> 0
A14: C3 | B14: =B88 -> 0 | C14: =C88 -> 0 | D14: =D88 -> 0 | E14: =E88 -> 0 | F14: =F88 -> 0 | G14: =G88 -> 0 | H14: =H88 -> 0 | I14: =I88 -> 0 | ... U14: =U88 -> 0
A15: C4 | B15: =B97 -> 0 | C15: =C97 -> 0 | D15: =D97 -> 0 | E15: =E97 -> 0 | F15: =F97 -> 0 | G15: =G97 -> 0 | H15: =H97 -> 0 | I15: =I97 -> 0 | ... U15: =U97 -> 0
A16: C5 | B16: =B106 -> 0 | C16: =C106 -> 0 | D16: =D106 -> 0 | E16: =E106 -> 0 | F16: =F106 -> 0 | G16: =G106 -> 0 | H16: =H106 -> 0 | I16: =I106 -> 0 | ... U16: =U106 -> 0
A18: P1 | B18: 1 | C18: 2 | D18: 3 | E18: 4 | F18: 5 | G18: 6 | H18: 7 | I18: 8 | J18: 9 | K18: 10 | L18: 11 | M18: 12 | N18: 13 | O18: 14 | P18: 15 | Q18: 16 | R18: 17 | S18: 18 | T18: 19 | U18: 20
A19: NB | R19: ='Datos de Entrada (1)'!B7 -> 100 | S19: ='Datos de Entrada (1)'!C7 -> 80 | T19: ='Datos de Entrada (1)'!D7 -> 100 | U19: ='Datos de Entrada (1)'!E7 -> 120
A20: EXITS | B20: ='Datos de Entrada (1)'!$E$18 -> 70 | C20: =B20+B24-B19 -> 70 | D20: =C20+C24-C19 -> 70 | E20: =D20+D24-D19 -> 70 | F20: =E20+E24-E19 -> 70 | G20: =F20+F24-F19 -> 70 | H20: =G20+G24-G19 -> 70 | I20: =H20+H24-H19 -> 70 | J20: =I20+I24-I19 -> 70 | ... U20: =T20+T24-T19 -> 50
A21: NN | B21: =IF(B19=0,0,MAX(0,B19+'Datos de Entrada (1)'!$B$18-'LANZ PP'!B20)) -> 0 | C21: =IF(C19=0,0,MAX(0,C19+'Datos de Entrada (1)'!$B$18-'LANZ PP'!C20)) -> 0 | D21: =IF(D19=0,0,MAX(0,D19+'Datos de Entrada (1)'!$B$18-'LANZ PP'!D20)) -> 0 | E21: =IF(E19=0,0,MAX(0,E19+'Datos de Entrada (1)'!$B$18-'LANZ PP'!E20)) -> 0 | F21: =IF(F19=0,0,MAX(0,F19+'Datos de Entrada (1)'!$B$18-'LANZ PP'!F20)) -> 0 | G21: =IF(G19=0,0,MAX(0,G19+'Datos de Entrada (1)'!$B$18-'LANZ PP'!G20)) -> 0 | H21: =IF(H19=0,0,MAX(0,H19+'Datos de Entrada (1)'!$B$18-'LANZ PP'!H20)) -> 0 | I21: =IF(I19=0,0,MAX(0,I19+'Datos de Entrada (1)'!$B$18-'LANZ PP'!I20)) -> 0 | ... U21: =IF(U19=0,0,MAX(0,U19+'Datos de Entrada (1)'!$B$18-'LANZ PP'!U20)) -> 120
A22: AUXILIAR (NN, CON DEFECTOS) | B22: =ROUNDUP(B21/(1-('Datos de Entrada (1)'!$D$18/100)),0) -> 0 | C22: =ROUNDUP(C21/(1-('Datos de Entrada (1)'!$D$18/100)),0) -> 0 | D22: =ROUNDUP(D21/(1-('Datos de Entrada (1)'!$D$18/100)),0) -> 0 | E22: =ROUNDUP(E21/(1-('Datos de Entrada (1)'!$D$18/100)),0) -> 0 | F22: =ROUNDUP(F21/(1-('Datos de Entrada (1)'!$D$18/100)),0) -> 0 | G22: =ROUNDUP(G21/(1-('Datos de Entrada (1)'!$D$18/100)),0) -> 0 | H22: =ROUNDUP(H21/(1-('Datos de Entrada (1)'!$D$18/100)),0) -> 0 | I22: =ROUNDUP(I21/(1-('Datos de Entrada (1)'!$D$18/100)),0) -> 0 | ... U22: =ROUNDUP(U21/(1-('Datos de Entrada (1)'!$D$18/100)),0) -> 120
A23: RPP | B23: =ROUNDUP(B22/'Datos de Entrada (1)'!$F$18,0)*'Datos de Entrada (1)'!$F$18 -> 0 | C23: =ROUNDUP(C22/'Datos de Entrada (1)'!$F$18,0)*'Datos de Entrada (1)'!$F$18 -> 0 | D23: =ROUNDUP(D22/'Datos de Entrada (1)'!$F$18,0)*'Datos de Entrada (1)'!$F$18 -> 0 | E23: =ROUNDUP(E22/'Datos de Entrada (1)'!$F$18,0)*'Datos de Entrada (1)'!$F$18 -> 0 | F23: =ROUNDUP(F22/'Datos de Entrada (1)'!$F$18,0)*'Datos de Entrada (1)'!$F$18 -> 0 | G23: =ROUNDUP(G22/'Datos de Entrada (1)'!$F$18,0)*'Datos de Entrada (1)'!$F$18 -> 0 | H23: =ROUNDUP(H22/'Datos de Entrada (1)'!$F$18,0)*'Datos de Entrada (1)'!$F$18 -> 0 | I23: =ROUNDUP(I22/'Datos de Entrada (1)'!$F$18,0)*'Datos de Entrada (1)'!$F$18 -> 0 | ... U23: =ROUNDUP(U22/'Datos de Entrada (1)'!$F$18,0)*'Datos de Entrada (1)'!$F$18 -> 120
A24: AUXILIAR 3 (CORRECTAS) | B24: =ROUNDDOWN(B23*(1-('Datos de Entrada (1)'!$D$18/100)),0) -> 0 | C24: =ROUNDDOWN(C23*(1-('Datos de Entrada (1)'!$D$18/100)),0) -> 0 | D24: =ROUNDDOWN(D23*(1-('Datos de Entrada (1)'!$D$18/100)),0) -> 0 | E24: =ROUNDDOWN(E23*(1-('Datos de Entrada (1)'!$D$18/100)),0) -> 0 | F24: =ROUNDDOWN(F23*(1-('Datos de Entrada (1)'!$D$18/100)),0) -> 0 | G24: =ROUNDDOWN(G23*(1-('Datos de Entrada (1)'!$D$18/100)),0) -> 0 | H24: =ROUNDDOWN(H23*(1-('Datos de Entrada (1)'!$D$18/100)),0) -> 0 | I24: =ROUNDDOWN(I23*(1-('Datos de Entrada (1)'!$D$18/100)),0) -> 0 | ... U24: =ROUNDDOWN(U23*(1-('Datos de Entrada (1)'!$D$18/100)),0) -> 120
A25: LANZ PP (EN CUENTA DEF. Y LOTE) | B25: =OFFSET(B23,0,'Datos de Entrada (1)'!$C$18) -> 0 | C25: =OFFSET(C23,0,'Datos de Entrada (1)'!$C$18) -> 0 | D25: =OFFSET(D23,0,'Datos de Entrada (1)'!$C$18) -> 0 | E25: =OFFSET(E23,0,'Datos de Entrada (1)'!$C$18) -> 0 | F25: =OFFSET(F23,0,'Datos de Entrada (1)'!$C$18) -> 0 | G25: =OFFSET(G23,0,'Datos de Entrada (1)'!$C$18) -> 0 | H25: =OFFSET(H23,0,'Datos de Entrada (1)'!$C$18) -> 0 | I25: =OFFSET(I23,0,'Datos de Entrada (1)'!$C$18) -> 0 | ... U25: =OFFSET(U23,0,'Datos de Entrada (1)'!$C$18) -> 0
A27: P2 | B27: 1 | C27: 2 | D27: 3 | E27: 4 | F27: 5 | G27: 6 | H27: 7 | I27: 8 | J27: 9 | K27: 10 | L27: 11 | M27: 12 | N27: 13 | O27: 14 | P27: 15 | Q27: 16 | R27: 17 | S27: 18 | T27: 19 | U27: 20
A28: NB | R28: ='Datos de Entrada (1)'!B8 -> 200 | S28: ='Datos de Entrada (1)'!C8 -> 200 | T28: ='Datos de Entrada (1)'!D8 -> 200 | U28: ='Datos de Entrada (1)'!E8 -> 250
A29: EXITS | B29: ='Datos de Entrada (1)'!$E$19 -> 120 | C29: =B29+B33-B28 -> 120 | D29: =C29+C33-C28 -> 120 | E29: =D29+D33-D28 -> 120 | F29: =E29+E33-E28 -> 120 | G29: =F29+F33-F28 -> 120 | H29: =G29+G33-G28 -> 120 | I29: =H29+H33-H28 -> 120 | J29: =I29+I33-I28 -> 120 | ... U29: =T29+T33-T28 -> 100
A30: NN | B30: =IF(B28=0,0,MAX(0,B28+'Datos de Entrada (1)'!$B$19-'LANZ PP'!B29)) -> 0 | C30: =IF(C28=0,0,MAX(0,C28+'Datos de Entrada (1)'!$B$19-'LANZ PP'!C29)) -> 0 | D30: =IF(D28=0,0,MAX(0,D28+'Datos de Entrada (1)'!$B$19-'LANZ PP'!D29)) -> 0 | E30: =IF(E28=0,0,MAX(0,E28+'Datos de Entrada (1)'!$B$19-'LANZ PP'!E29)) -> 0 | F30: =IF(F28=0,0,MAX(0,F28+'Datos de Entrada (1)'!$B$19-'LANZ PP'!F29)) -> 0 | G30: =IF(G28=0,0,MAX(0,G28+'Datos de Entrada (1)'!$B$19-'LANZ PP'!G29)) -> 0 | H30: =IF(H28=0,0,MAX(0,H28+'Datos de Entrada (1)'!$B$19-'LANZ PP'!H29)) -> 0 | I30: =IF(I28=0,0,MAX(0,I28+'Datos de Entrada (1)'!$B$19-'LANZ PP'!I29)) -> 0 | ... U30: =IF(U28=0,0,MAX(0,U28+'Datos de Entrada (1)'!$B$19-'LANZ PP'!U29)) -> 250
A31: AUXILIAR (NN, CON DEFECTOS) | B31: =ROUNDUP(B30/(1-('Datos de Entrada (1)'!$D$19/100)),0) -> 0 | C31: =ROUNDUP(C30/(1-('Datos de Entrada (1)'!$D$19/100)),0) -> 0 | D31: =ROUNDUP(D30/(1-('Datos de Entrada (1)'!$D$19/100)),0) -> 0 | E31: =ROUNDUP(E30/(1-('Datos de Entrada (1)'!$D$19/100)),0) -> 0 | F31: =ROUNDUP(F30/(1-('Datos de Entrada (1)'!$D$19/100)),0) -> 0 | G31: =ROUNDUP(G30/(1-('Datos de Entrada (1)'!$D$19/100)),0) -> 0 | H31: =ROUNDUP(H30/(1-('Datos de Entrada (1)'!$D$19/100)),0) -> 0 | I31: =ROUNDUP(I30/(1-('Datos de Entrada (1)'!$D$19/100)),0) -> 0 | ... U31: =ROUNDUP(U30/(1-('Datos de Entrada (1)'!$D$19/100)),0) -> 250
A32: RPP | B32: =ROUNDUP(B31/'Datos de Entrada (1)'!$F$19,0)*'Datos de Entrada (1)'!$F$19 -> 0 | C32: =ROUNDUP(C31/'Datos de Entrada (1)'!$F$19,0)*'Datos de Entrada (1)'!$F$19 -> 0 | D32: =ROUNDUP(D31/'Datos de Entrada (1)'!$F$19,0)*'Datos de Entrada (1)'!$F$19 -> 0 | E32: =ROUNDUP(E31/'Datos de Entrada (1)'!$F$19,0)*'Datos de Entrada (1)'!$F$19 -> 0 | F32: =ROUNDUP(F31/'Datos de Entrada (1)'!$F$19,0)*'Datos de Entrada (1)'!$F$19 -> 0 | G32: =ROUNDUP(G31/'Datos de Entrada (1)'!$F$19,0)*'Datos de Entrada (1)'!$F$19 -> 0 | H32: =ROUNDUP(H31/'Datos de Entrada (1)'!$F$19,0)*'Datos de Entrada (1)'!$F$19 -> 0 | I32: =ROUNDUP(I31/'Datos de Entrada (1)'!$F$19,0)*'Datos de Entrada (1)'!$F$19 -> 0 | ... U32: =ROUNDUP(U31/'Datos de Entrada (1)'!$F$19,0)*'Datos de Entrada (1)'!$F$19 -> 250
A33: AUXILIAR 3 (CORRECTAS) | B33: =ROUNDDOWN(B32*(1-('Datos de Entrada (1)'!$D$19/100)),0) -> 0 | C33: =ROUNDDOWN(C32*(1-('Datos de Entrada (1)'!$D$19/100)),0) -> 0 | D33: =ROUNDDOWN(D32*(1-('Datos de Entrada (1)'!$D$19/100)),0) -> 0 | E33: =ROUNDDOWN(E32*(1-('Datos de Entrada (1)'!$D$19/100)),0) -> 0 | F33: =ROUNDDOWN(F32*(1-('Datos de Entrada (1)'!$D$19/100)),0) -> 0 | G33: =ROUNDDOWN(G32*(1-('Datos de Entrada (1)'!$D$19/100)),0) -> 0 | H33: =ROUNDDOWN(H32*(1-('Datos de Entrada (1)'!$D$19/100)),0) -> 0 | I33: =ROUNDDOWN(I32*(1-('Datos de Entrada (1)'!$D$19/100)),0) -> 0 | ... U33: =ROUNDDOWN(U32*(1-('Datos de Entrada (1)'!$D$19/100)),0) -> 250
A34: LANZ PP (EN CUENTA DEF. Y LOTE) | B34: =OFFSET(B32,0,'Datos de Entrada (1)'!$C$19) -> 0 | C34: =OFFSET(C32,0,'Datos de Entrada (1)'!$C$19) -> 0 | D34: =OFFSET(D32,0,'Datos de Entrada (1)'!$C$19) -> 0 | E34: =OFFSET(E32,0,'Datos de Entrada (1)'!$C$19) -> 0 | F34: =OFFSET(F32,0,'Datos de Entrada (1)'!$C$19) -> 0 | G34: =OFFSET(G32,0,'Datos de Entrada (1)'!$C$19) -> 0 | H34: =OFFSET(H32,0,'Datos de Entrada (1)'!$C$19) -> 0 | I34: =OFFSET(I32,0,'Datos de Entrada (1)'!$C$19) -> 0 | ... U34: =OFFSET(U32,0,'Datos de Entrada (1)'!$C$19) -> 0
A36: S11 | B36: 1 | C36: 2 | D36: 3 | E36: 4 | F36: 5 | G36: 6 | H36: 7 | I36: 8 | J36: 9 | K36: 10 | L36: 11 | M36: 12 | N36: 13 | O36: 14 | P36: 15 | Q36: 16 | R36: 17 | S36: 18 | T36: 19 | U36: 20
A37: NB | B37: ='Datos de Entrada (2)'!$G$5*'LANZ PP'!B25 -> 0 | C37: ='Datos de Entrada (2)'!$G$5*'LANZ PP'!C25 -> 0 | D37: ='Datos de Entrada (2)'!$G$5*'LANZ PP'!D25 -> 0 | E37: ='Datos de Entrada (2)'!$G$5*'LANZ PP'!E25 -> 0 | F37: ='Datos de Entrada (2)'!$G$5*'LANZ PP'!F25 -> 0 | G37: ='Datos de Entrada (2)'!$G$5*'LANZ PP'!G25 -> 0 | H37: ='Datos de Entrada (2)'!$G$5*'LANZ PP'!H25 -> 0 | I37: ='Datos de Entrada (2)'!$G$5*'LANZ PP'!I25 -> 0 | ... U37: ='Datos de Entrada (2)'!$G$5*'LANZ PP'!U25 -> 0
A38: EXITS | B38: ='Datos de Entrada (1)'!$E$20 -> 20 | C38: =B38+B42-B37 -> 20 | D38: =C38+C42-C37 -> 20 | E38: =D38+D42-D37 -> 20 | F38: =E38+E42-E37 -> 20 | G38: =F38+F42-F37 -> 20 | H38: =G38+G42-G37 -> 20 | I38: =H38+H42-H37 -> 20 | J38: =I38+I42-I37 -> 20 | ... U38: =T38+T42-T37 -> 40
A39: NN | B39: =IF(B37=0,0,MAX(0,B37+'Datos de Entrada (1)'!$B$20-'LANZ PP'!B38)) -> 0 | C39: =IF(C37=0,0,MAX(0,C37+'Datos de Entrada (1)'!$B$20-'LANZ PP'!C38)) -> 0 | D39: =IF(D37=0,0,MAX(0,D37+'Datos de Entrada (1)'!$B$20-'LANZ PP'!D38)) -> 0 | E39: =IF(E37=0,0,MAX(0,E37+'Datos de Entrada (1)'!$B$20-'LANZ PP'!E38)) -> 0 | F39: =IF(F37=0,0,MAX(0,F37+'Datos de Entrada (1)'!$B$20-'LANZ PP'!F38)) -> 0 | G39: =IF(G37=0,0,MAX(0,G37+'Datos de Entrada (1)'!$B$20-'LANZ PP'!G38)) -> 0 | H39: =IF(H37=0,0,MAX(0,H37+'Datos de Entrada (1)'!$B$20-'LANZ PP'!H38)) -> 0 | I39: =IF(I37=0,0,MAX(0,I37+'Datos de Entrada (1)'!$B$20-'LANZ PP'!I38)) -> 0 | ... U39: =IF(U37=0,0,MAX(0,U37+'Datos de Entrada (1)'!$B$20-'LANZ PP'!U38)) -> 0
A40: AUXILIAR (NN, CON DEFECTOS) | B40: =ROUNDUP(B39/(1-('Datos de Entrada (1)'!$D$20/100)),0) -> 0 | C40: =ROUNDUP(C39/(1-('Datos de Entrada (1)'!$D$20/100)),0) -> 0 | D40: =ROUNDUP(D39/(1-('Datos de Entrada (1)'!$D$20/100)),0) -> 0 | E40: =ROUNDUP(E39/(1-('Datos de Entrada (1)'!$D$20/100)),0) -> 0 | F40: =ROUNDUP(F39/(1-('Datos de Entrada (1)'!$D$20/100)),0) -> 0 | G40: =ROUNDUP(G39/(1-('Datos de Entrada (1)'!$D$20/100)),0) -> 0 | H40: =ROUNDUP(H39/(1-('Datos de Entrada (1)'!$D$20/100)),0) -> 0 | I40: =ROUNDUP(I39/(1-('Datos de Entrada (1)'!$D$20/100)),0) -> 0 | ... U40: =ROUNDUP(U39/(1-('Datos de Entrada (1)'!$D$20/100)),0) -> 0
A41: RPP | B41: =ROUNDUP(B40/'Datos de Entrada (1)'!$F$20,0)*'Datos de Entrada (1)'!$F$20 -> 0 | C41: =ROUNDUP(C40/'Datos de Entrada (1)'!$F$20,0)*'Datos de Entrada (1)'!$F$20 -> 0 | D41: =ROUNDUP(D40/'Datos de Entrada (1)'!$F$20,0)*'Datos de Entrada (1)'!$F$20 -> 0 | E41: =ROUNDUP(E40/'Datos de Entrada (1)'!$F$20,0)*'Datos de Entrada (1)'!$F$20 -> 0 | F41: =ROUNDUP(F40/'Datos de Entrada (1)'!$F$20,0)*'Datos de Entrada (1)'!$F$20 -> 0 | G41: =ROUNDUP(G40/'Datos de Entrada (1)'!$F$20,0)*'Datos de Entrada (1)'!$F$20 -> 0 | H41: =ROUNDUP(H40/'Datos de Entrada (1)'!$F$20,0)*'Datos de Entrada (1)'!$F$20 -> 0 | I41: =ROUNDUP(I40/'Datos de Entrada (1)'!$F$20,0)*'Datos de Entrada (1)'!$F$20 -> 0 | ... U41: =ROUNDUP(U40/'Datos de Entrada (1)'!$F$20,0)*'Datos de Entrada (1)'!$F$20 -> 0
A42: AUXILIAR 3 (CORRECTAS) | B42: =ROUNDDOWN(B41*(1-('Datos de Entrada (1)'!$D$20/100)),0) -> 0 | C42: =ROUNDDOWN(C41*(1-('Datos de Entrada (1)'!$D$20/100)),0) -> 0 | D42: =ROUNDDOWN(D41*(1-('Datos de Entrada (1)'!$D$20/100)),0) -> 0 | E42: =ROUNDDOWN(E41*(1-('Datos de Entrada (1)'!$D$20/100)),0) -> 0 | F42: =ROUNDDOWN(F41*(1-('Datos de Entrada (1)'!$D$20/100)),0) -> 0 | G42: =ROUNDDOWN(G41*(1-('Datos de Entrada (1)'!$D$20/100)),0) -> 0 | H42: =ROUNDDOWN(H41*(1-('Datos de Entrada (1)'!$D$20/100)),0) -> 0 | I42: =ROUNDDOWN(I41*(1-('Datos de Entrada (1)'!$D$20/100)),0) -> 0 | ... U42: =ROUNDDOWN(U41*(1-('Datos de Entrada (1)'!$D$20/100)),0) -> 0
A43: LANZ PP (EN CUENTA DEF. Y LOTE) | B43: =OFFSET(B41,0,'Datos de Entrada (1)'!$C$20) -> 0 | C43: =OFFSET(C41,0,'Datos de Entrada (1)'!$C$20) -> 0 | D43: =OFFSET(D41,0,'Datos de Entrada (1)'!$C$20) -> 0 | E43: =OFFSET(E41,0,'Datos de Entrada (1)'!$C$20) -> 0 | F43: =OFFSET(F41,0,'Datos de Entrada (1)'!$C$20) -> 0 | G43: =OFFSET(G41,0,'Datos de Entrada (1)'!$C$20) -> 0 | H43: =OFFSET(H41,0,'Datos de Entrada (1)'!$C$20) -> 0 | I43: =OFFSET(I41,0,'Datos de Entrada (1)'!$C$20) -> 0 | ... U43: =OFFSET(U41,0,'Datos de Entrada (1)'!$C$20) -> 0
A45: S12 | B45: 1 | C45: 2 | D45: 3 | E45: 4 | F45: 5 | G45: 6 | H45: 7 | I45: 8 | J45: 9 | K45: 10 | L45: 11 | M45: 12 | N45: 13 | O45: 14 | P45: 15 | Q45: 16 | R45: 17 | S45: 18 | T45: 19 | U45: 20
...

Sheet LANZ PP CAMBIOS
A1: Informe de Explosión de Necesidades de un sistema MRP-I
A2: Planificación de Necesidades de Materiales (MRP) (LANZ PP)
C3: Modificación para poder cambiar en el PMP el número de la semana o el producto deseado, manteniendo las dimensiones actuales de la tabla PMP
B4: HOY
B5: LANZ PP | R5: SEMANA
A6: PRODUCTO | B6: 1 | C6: 2 | D6: 3 | E6: 4 | F6: 5 | G6: 6 | H6: 7 | I6: 8 | J6: 9 | K6: 10 | L6: 11 | M6: 12 | N6: 13 | O6: 14 | P6: 15 | Q6: 16 | R6: 17 | S6: 18 | T6: 19 | U6: 20
A7: P1 | B7: =B25 -> 0 | C7: =C25 -> 0 | D7: =D25 -> 0 | E7: =E25 -> 0 | F7: =F25 -> 0 | G7: =G25 -> 0 | H7: =H25 -> 0 | I7: =I25 -> 0 | ... U7: =U25 -> 0
A8: P2 | B8: =B34 -> 0 | C8: =C34 -> 0 | D8: =D34 -> 0 | E8: =E34 -> 0 | F8: =F34 -> 0 | G8: =G34 -> 0 | H8: =H34 -> 0 | I8: =I34 -> 0 | ... U8: =U34 -> 0
A9: S11 | B9: =B43 -> 0 | C9: =C43 -> 0 | D9: =D43 -> 0 | E9: =E43 -> 0 | F9: =F43 -> 0 | G9: =G43 -> 0 | H9: =H43 -> 0 | I9: =I43 -> 0 | ... U9: =U43 -> 0
A10: S12 | B10: =B52 -> 0 | C10: =C52 -> 0 | D10: =D52 -> 0 | E10: =E52 -> 0 | F10: =F52 -> 0 | G10: =G52 -> 0 | H10: =H52 -> 0 | I10: =I52 -> 0 | ... U10: =U52 -> 0
A11: S13 | B11: =B61 -> 0 | C11: =C61 -> 0 | D11: =D61 -> 0 | E11: =E61 -> 0 | F11: =F61 -> 0 | G11: =G61 -> 0 | H11: =H61 -> 0 | I11: =I61 -> 0 | ... U11: =U61 -> 0
A12: C1 | B12: =B70 -> 0 | C12: =C70 -> 0 | D12: =D70 -> 0 | E12: =E70 -> 0 | F12: =F70 -> 0 | G12: =G70 -> 0 | H12: =H70 -> 0 | I12: =I70 -> 0 | ... U12: =U70 -> 0
A13: C2 | B13: =B79 -> 0 | C13: =C79 -> 0 | D13: =D79 -> 0 | E13: =E79 -> 0 | F13: =F79 -> 0 | G13: =G79 -> 0 | H13: =H79 -> 0 | I13: =I79 -> 0 | ... U13: =U79 -> 0
A14: C3 | B14: =B88 -> 0 | C14: =C88 -> 0 | D14: =D88 -> 0 | E14: =E88 -> 0 | F14: =F88 -> 0 | G14: =G88 -> 0 | H14: =H88 -> 0 | I14: =I88 -> 0 | ... U14: =U88 -> 0
A15: C4 | B15: =B97 -> 0 | C15: =C97 -> 0 | D15: =D97 -> 0 | E15: =E97 -> 0 | F15: =F97 -> 0 | G15: =G97 -> 0 | H15: =H97 -> 0 | I15: =I97 -> 0 | ... U15: =U97 -> 0
A16: C5 | B16: =B106 -> 0 | C16: =C106 -> 0 | D16: =D106 -> 0 | E16: =E106 -> 0 | F16: =F106 -> 0 | G16: =G106 -> 0 | H16: =H106 -> 0 | I16: =I106 -> 0 | ... U16: =U106 -> 0
A18: P1 | B18: 1 | C18: 2 | D18: 3 | E18: 4 | F18: 5 | G18: 6 | H18: 7 | I18: 8 | J18: 9 | K18: 10 | L18: 11 | M18: 12 | N18: 13 | O18: 14 | P18: 15 | Q18: 16 | R18: 17 | S18: 18 | T18: 19 | U18: 20
A19: NB | B19: =IFERROR(VLOOKUP($A$7,'Datos de Entrada (1)'!$A$7:$E$10,MATCH(B18,'Datos de Entrada (1)'!$A$6:$E$6,0),0),0) -> 0 | C19: =IFERROR(VLOOKUP($A$7,'Datos de Entrada (1)'!$A$7:$E$10,MATCH(C18,'Datos de Entrada (1)'!$A$6:$E$6,0),0),0) -> 0 | D19: =IFERROR(VLOOKUP($A$7,'Datos de Entrada (1)'!$A$7:$E$10,MATCH(D18,'Datos de Entrada (1)'!$A$6:$E$6,0),0),0) -> 0 | E19: =IFERROR(VLOOKUP($A$7,'Datos de Entrada (1)'!$A$7:$E$10,MATCH(E18,'Datos de Entrada (1)'!$A$6:$E$6,0),0),0) -> 0 | F19: =IFERROR(VLOOKUP($A$7,'Datos de Entrada (1)'!$A$7:$E$10,MATCH(F18,'Datos de Entrada (1)'!$A$6:$E$6,0),0),0) -> 0 | G19: =IFERROR(VLOOKUP($A$7,'Datos de Entrada (1)'!$A$7:$E$10,MATCH(G18,'Datos de Entrada (1)'!$A$6:$E$6,0),0),0) -> 0 | H19: =IFERROR(VLOOKUP($A$7,'Datos de Entrada (1)'!$A$7:$E$10,MATCH(H18,'Datos de Entrada (1)'!$A$6:$E$6,0),0),0) -> 0 | I19: =IFERROR(VLOOKUP($A$7,'Datos de Entrada (1)'!$A$7:$E$10,MATCH(I18,'Datos de Entrada (1)'!$A$6:$E$6,0),0),0) -> 0 | ... U19: =IFERROR(VLOOKUP($A$7,'Datos de Entrada (1)'!$A$7:$E$10,MATCH(U18,'Datos de Entrada (1)'!$A$6:$E$6,0),0),0) -> 120
A20: EXITS | B20: ='Datos de Entrada (1)'!$E$18 -> 70 | C20: =B20+B24-B19 -> 70 | D20: =C20+C24-C19 -> 70 | E20: =D20+D24-D19 -> 70 | F20: =E20+E24-E19 -> 70 | G20: =F20+F24-F19 -> 70 | H20: =G20+G24-G19 -> 70 | I20: =H20+H24-H19 -> 70 | J20: =I20+I24-I19 -> 70 | ... U20: =T20+T24-T19 -> 50
A21: NN | B21: =IF(B19=0,0,MAX(0,B19+'Datos de Entrada (1)'!$B$18-'LANZ PP'!B20)) -> 0 | C21: =IF(C19=0,0,MAX(0,C19+'Datos de Entrada (1)'!$B$18-'LANZ PP'!C20)) -> 0 | D21: =IF(D19=0,0,MAX(0,D19+'Datos de Entrada (1)'!$B$18-'LANZ PP'!D20)) -> 0 | E21: =IF(E19=0,0,MAX(0,E19+'Datos de Entrada (1)'!$B$18-'LANZ PP'!E20)) -> 0 | F21: =IF(F19=0,0,MAX(0,F19+'Datos de Entrada (1)'!$B$18-'LANZ PP'!F20)) -> 0 | G21: =IF(G19=0,0,MAX(0,G19+'Datos de Entrada (1)'!$B$18-'LANZ PP'!G20)) -> 0 | H21: =IF(H19=0,0,MAX(0,H19+'Datos de Entrada (1)'!$B$18-'LANZ PP'!H20)) -> 0 | I21: =IF(I19=0,0,MAX(0,I19+'Datos de Entrada (1)'!$B$18-'LANZ PP'!I20)) -> 0 | ... U21: =IF(U19=0,0,MAX(0,U19+'Datos de Entrada (1)'!$B$18-'LANZ PP'!U20)) -> 120
A22: AUXILIAR (NN, CON DEFECTOS) | B22: =ROUNDUP(B21/(1-('Datos de Entrada (1)'!$D$18/100)),0) -> 0 | C22: =ROUNDUP(C21/(1-('Datos de Entrada (1)'!$D$18/100)),0) -> 0 | D22: =ROUNDUP(D21/(1-('Datos de Entrada (1)'!$D$18/100)),0) -> 0 | E22: =ROUNDUP(E21/(1-('Datos de Entrada (1)'!$D$18/100)),0) -> 0 | F22: =ROUNDUP(F21/(1-('Datos de Entrada (1)'!$D$18/100)),0) -> 0 | G22: =ROUNDUP(G21/(1-('Datos de Entrada (1)'!$D$18/100)),0) -> 0 | H22: =ROUNDUP(H21/(1-('Datos de Entrada (1)'!$D$18/100)),0) -> 0 | I22: =ROUNDUP(I21/(1-('Datos de Entrada (1)'!$D$18/100)),0) -> 0 | ... U22: =ROUNDUP(U21/(1-('Datos de Entrada (1)'!$D$18/100)),0) -> 120
A23: RPP | B23: =ROUNDUP(B22/'Datos de Entrada (1)'!$F$18,0)*'Datos de Entrada (1)'!$F$18 -> 0 | C23: =ROUNDUP(C22/'Datos de Entrada (1)'!$F$18,0)*'Datos de Entrada (1)'!$F$18 -> 0 | D23: =ROUNDUP(D22/'Datos de Entrada (1)'!$F$18,0)*'Datos de Entrada (1)'!$F$18 -> 0 | E23: =ROUNDUP(E22/'Datos de Entrada (1)'!$F$18,0)*'Datos de Entrada (1)'!$F$18 -> 0 | F23: =ROUNDUP(F22/'Datos de Entrada (1)'!$F$18,0)*'Datos de Entrada (1)'!$F$18 -> 0 | G23: =ROUNDUP(G22/'Datos de Entrada (1)'!$F$18,0)*'Datos de Entrada (1)'!$F$18 -> 0 | H23: =ROUNDUP(H22/'Datos de Entrada (1)'!$F$18,0)*'Datos de Entrada (1)'!$F$18 -> 0 | I23: =ROUNDUP(I22/'Datos de Entrada (1)'!$F$18,0)*'Datos de Entrada (1)'!$F$18 -> 0 | ... U23: =ROUNDUP(U22/'Datos de Entrada (1)'!$F$18,0)*'Datos de Entrada (1)'!$F$18 -> 120
A24: AUXILIAR 3 (CORRECTAS) | B24: =ROUNDDOWN(B23*(1-('Datos de Entrada (1)'!$D$18/100)),0) -> 0 | C24: =ROUNDDOWN(C23*(1-('Datos de Entrada (1)'!$D$18/100)),0) -> 0 | D24: =ROUNDDOWN(D23*(1-('Datos de Entrada (1)'!$D$18/100)),0) -> 0 | E24: =ROUNDDOWN(E23*(1-('Datos de Entrada (1)'!$D$18/100)),0) -> 0 | F24: =ROUNDDOWN(F23*(1-('Datos de Entrada (1)'!$D$18/100)),0) -> 0 | G24: =ROUNDDOWN(G23*(1-('Datos de Entrada (1)'!$D$18/100)),0) -> 0 | H24: =ROUNDDOWN(H23*(1-('Datos de Entrada (1)'!$D$18/100)),0) -> 0 | I24: =ROUNDDOWN(I23*(1-('Datos de Entrada (1)'!$D$18/100)),0) -> 0 | ... U24: =ROUNDDOWN(U23*(1-('Datos de Entrada (1)'!$D$18/100)),0) -> 120
A25: LANZ PP (EN CUENTA DEF. Y LOTE) | B25: =OFFSET(B23,0,'Datos de Entrada (1)'!$C$18) -> 0 | C25: =OFFSET(C23,0,'Datos de Entrada (1)'!$C$18) -> 0 | D25: =OFFSET(D23,0,'Datos de Entrada (1)'!$C$18) -> 0 | E25: =OFFSET(E23,0,'Datos de Entrada (1)'!$C$18) -> 0 | F25: =OFFSET(F23,0,'Datos de Entrada (1)'!$C$18) -> 0 | G25: =OFFSET(G23,0,'Datos de Entrada (1)'!$C$18) -> 0 | H25: =OFFSET(H23,0,'Datos de Entrada (1)'!$C$18) -> 0 | I25: =OFFSET(I23,0,'Datos de Entrada (1)'!$C$18) -> 0 | ... U25: =OFFSET(U23,0,'Datos de Entrada (1)'!$C$18) -> 0
A27: P2 | B27: 1 | C27: 2 | D27: 3 | E27: 4 | F27: 5 | G27: 6 | H27: 7 | I27: 8 | J27: 9 | K27: 10 | L27: 11 | M27: 12 | N27: 13 | O27: 14 | P27: 15 | Q27: 16 | R27: 17 | S27: 18 | T27: 19 | U27: 20
A28: NB | B28: =IFERROR(VLOOKUP($A$8,'Datos de Entrada (1)'!$A$7:$E$10,MATCH(B27,'Datos de Entrada (1)'!$A$6:$E$6,0),0),0) -> 0 | C28: =IFERROR(VLOOKUP($A$8,'Datos de Entrada (1)'!$A$7:$E$10,MATCH(C27,'Datos de Entrada (1)'!$A$6:$E$6,0),0),0) -> 0 | D28: =IFERROR(VLOOKUP($A$8,'Datos de Entrada (1)'!$A$7:$E$10,MATCH(D27,'Datos de Entrada (1)'!$A$6:$E$6,0),0),0) -> 0 | E28: =IFERROR(VLOOKUP($A$8,'Datos de Entrada (1)'!$A$7:$E$10,MATCH(E27,'Datos de Entrada (1)'!$A$6:$E$6,0),0),0) -> 0 | F28: =IFERROR(VLOOKUP($A$8,'Datos de Entrada (1)'!$A$7:$E$10,MATCH(F27,'Datos de Entrada (1)'!$A$6:$E$6,0),0),0) -> 0 | G28: =IFERROR(VLOOKUP($A$8,'Datos de Entrada (1)'!$A$7:$E$10,MATCH(G27,'Datos de Entrada (1)'!$A$6:$E$6,0),0),0) -> 0 | H28: =IFERROR(VLOOKUP($A$8,'Datos de Entrada (1)'!$A$7:$E$10,MATCH(H27,'Datos de Entrada (1)'!$A$6:$E$6,0),0),0) -> 0 | I28: =IFERROR(VLOOKUP($A$8,'Datos de Entrada (1)'!$A$7:$E$10,MATCH(I27,'Datos de Entrada (1)'!$A$6:$E$6,0),0),0) -> 0 | ... U28: =IFERROR(VLOOKUP($A$8,'Datos de Entrada (1)'!$A$7:$E$10,MATCH(U27,'Datos de Entrada (1)'!$A$6:$E$6,0),0),0) -> 250
A29: EXITS | B29: ='Datos de Entrada (1)'!$E$19 -> 120 | C29: =B29+B33-B28 -> 120 | D29: =C29+C33-C28 -> 120 | E29: =D29+D33-D28 -> 120 | F29: =E29+E33-E28 -> 120 | G29: =F29+F33-F28 -> 120 | H29: =G29+G33-G28 -> 120 | I29: =H29+H33-H28 -> 120 | J29: =I29+I33-I28 -> 120 | ... U29: =T29+T33-T28 -> 100
A30: NN | B30: =IF(B28=0,0,MAX(0,B28+'Datos de Entrada (1)'!$B$19-'LANZ PP'!B29)) -> 0 | C30: =IF(C28=0,0,MAX(0,C28+'Datos de Entrada (1)'!$B$19-'LANZ PP'!C29)) -> 0 | D30: =IF(D28=0,0,MAX(0,D28+'Datos de Entrada (1)'!$B$19-'LANZ PP'!D29)) -> 0 | E30: =IF(E28=0,0,MAX(0,E28+'Datos de Entrada (1)'!$B$19-'LANZ PP'!E29)) -> 0 | F30: =IF(F28=0,0,MAX(0,F28+'Datos de Entrada (1)'!$B$19-'LANZ PP'!F29)) -> 0 | G30: =IF(G28=0,0,MAX(0,G28+'Datos de Entrada (1)'!$B$19-'LANZ PP'!G29)) -> 0 | H30: =IF(H28=0,0,MAX(0,H28+'Datos de Entrada (1)'!$B$19-'LANZ PP'!H29)) -> 0 | I30: =IF(I28=0,0,MAX(0,I28+'Datos de Entrada (1)'!$B$19-'LANZ PP'!I29)) -> 0 | ... U30: =IF(U28=0,0,MAX(0,U28+'Datos de Entrada (1)'!$B$19-'LANZ PP'!U29)) -> 250
A31: AUXILIAR (NN, CON DEFECTOS) | B31: =ROUNDUP(B30/(1-('Datos de Entrada (1)'!$D$19/100)),0) -> 0 | C31: =ROUNDUP(C30/(1-('Datos de Entrada (1)'!$D$19/100)),0) -> 0 | D31: =ROUNDUP(D30/(1-('Datos de Entrada (1)'!$D$19/100)),0) -> 0 | E31: =ROUNDUP(E30/(1-('Datos de Entrada (1)'!$D$19/100)),0) -> 0 | F31: =ROUNDUP(F30/(1-('Datos de Entrada (1)'!$D$19/100)),0) -> 0 | G31: =ROUNDUP(G30/(1-('Datos de Entrada (1)'!$D$19/100)),0) -> 0 | H31: =ROUNDUP(H30/(1-('Datos de Entrada (1)'!$D$19/100)),0) -> 0 | I31: =ROUNDUP(I30/(1-('Datos de Entrada (1)'!$D$19/100)),0) -> 0 | ... U31: =ROUNDUP(U30/(1-('Datos de Entrada (1)'!$D$19/100)),0) -> 250
A32: RPP | B32: =ROUNDUP(B31/'Datos de Entrada (1)'!$F$19,0)*'Datos de Entrada (1)'!$F$19 -> 0 | C32: =ROUNDUP(C31/'Datos de Entrada (1)'!$F$19,0)*'Datos de Entrada (1)'!$F$19 -> 0 | D32: =ROUNDUP(D31/'Datos de Entrada (1)'!$F$19,0)*'Datos de Entrada (1)'!$F$19 -> 0 | E32: =ROUNDUP(E31/'Datos de Entrada (1)'!$F$19,0)*'Datos de Entrada (1)'!$F$19 -> 0 | F32: =ROUNDUP(F31/'Datos de Entrada (1)'!$F$19,0)*'Datos de Entrada (1)'!$F$19 -> 0 | G32: =ROUNDUP(G31/'Datos de Entrada (1)'!$F$19,0)*'Datos de Entrada (1)'!$F$19 -> 0 | H32: =ROUNDUP(H31/'Datos de Entrada (1)'!$F$19,0)*'Datos de Entrada (1)'!$F$19 -> 0 | I32: =ROUNDUP(I31/'Datos de Entrada (1)'!$F$19,0)*'Datos de Entrada (1)'!$F$19 -> 0 | ... U32: =ROUNDUP(U31/'Datos de Entrada (1)'!$F$19,0)*'Datos de Entrada (1)'!$F$19 -> 250
A33: AUXILIAR 3 (CORRECTAS) | B33: =ROUNDDOWN(B32*(1-('Datos de Entrada (1)'!$D$19/100)),0) -> 0 | C33: =ROUNDDOWN(C32*(1-('Datos de Entrada (1)'!$D$19/100)),0) -> 0 | D33: =ROUNDDOWN(D32*(1-('Datos de Entrada (1)'!$D$19/100)),0) -> 0 | E33: =ROUNDDOWN(E32*(1-('Datos de Entrada (1)'!$D$19/100)),0) -> 0 | F33: =ROUNDDOWN(F32*(1-('Datos de Entrada (1)'!$D$19/100)),0) -> 0 | G33: =ROUNDDOWN(G32*(1-('Datos de Entrada (1)'!$D$19/100)),0) -> 0 | H33: =ROUNDDOWN(H32*(1-('Datos de Entrada (1)'!$D$19/100)),0) -> 0 | I33: =ROUNDDOWN(I32*(1-('Datos de Entrada (1)'!$D$19/100)),0) -> 0 | ... U33: =ROUNDDOWN(U32*(1-('Datos de Entrada (1)'!$D$19/100)),0) -> 250
A34: LANZ PP (EN CUENTA DEF. Y LOTE) | B34: =OFFSET(B32,0,'Datos de Entrada (1)'!$C$19) -> 0 | C34: =OFFSET(C32,0,'Datos de Entrada (1)'!$C$19) -> 0 | D34: =OFFSET(D32,0,'Datos de Entrada (1)'!$C$19) -> 0 | E34: =OFFSET(E32,0,'Datos de Entrada (1)'!$C$19) -> 0 | F34: =OFFSET(F32,0,'Datos de Entrada (1)'!$C$19) -> 0 | G34: =OFFSET(G32,0,'Datos de Entrada (1)'!$C$19) -> 0 | H34: =OFFSET(H32,0,'Datos de Entrada (1)'!$C$19) -> 0 | I34: =OFFSET(I32,0,'Datos de Entrada (1)'!$C$19) -> 0 | ... U34: =OFFSET(U32,0,'Datos de Entrada (1)'!$C$19) -> 0
A36: S11 | B36: 1 | C36: 2 | D36: 3 | E36: 4 | F36: 5 | G36: 6 | H36: 7 | I36: 8 | J36: 9 | K36: 10 | L36: 11 | M36: 12 | N36: 13 | O36: 14 | P36: 15 | Q36: 16 | R36: 17 | S36: 18 | T36: 19 | U36: 20
A37: NB | B37: ='Datos de Entrada (2)'!$G$5*'LANZ PP CAMBIOS'!B25+IFERROR(VLOOKUP($A$9,'Datos de Entrada (1)'!$A$7:$E$10,MATCH(B36,'Datos de Entrada (1)'!$A$6:$E$6,0),0),0) -> 0 | C37: ='Datos de Entrada (2)'!$G$5*'LANZ PP CAMBIOS'!C25+IFERROR(VLOOKUP($A$9,'Datos de Entrada (1)'!$A$7:$E$10,MATCH(C36,'Datos de Entrada (1)'!$A$6:$E$6,0),0),0) -> 0 | D37: ='Datos de Entrada (2)'!$G$5*'LANZ PP CAMBIOS'!D25+IFERROR(VLOOKUP($A$9,'Datos de Entrada (1)'!$A$7:$E$10,MATCH(D36,'Datos de Entrada (1)'!$A$6:$E$6,0),0),0) -> 0 | E37: ='Datos de Entrada (2)'!$G$5*'LANZ PP CAMBIOS'!E25+IFERROR(VLOOKUP($A$9,'Datos de Entrada (1)'!$A$7:$E$10,MATCH(E36,'Datos de Entrada (1)'!$A$6:$E$6,0),0),0) -> 0 | F37: ='Datos de Entrada (2)'!$G$5*'LANZ PP CAMBIOS'!F25+IFERROR(VLOOKUP($A$9,'Datos de Entrada (1)'!$A$7:$E$10,MATCH(F36,'Datos de Entrada (1)'!$A$6:$E$6,0),0),0) -> 0 | G37: ='Datos de Entrada (2)'!$G$5*'LANZ PP CAMBIOS'!G25+IFERROR(VLOOKUP($A$9,'Datos de Entrada (1)'!$A$7:$E$10,MATCH(G36,'Datos de Entrada (1)'!$A$6:$E$6,0),0),0) -> 0 | H37: ='Datos de Entrada (2)'!$G$5*'LANZ PP CAMBIOS'!H25+IFERROR(VLOOKUP($A$9,'Datos de Entrada (1)'!$A$7:$E$10,MATCH(H36,'Datos de Entrada (1)'!$A$6:$E$6,0),0),0) -> 0 | I37: ='Datos de Entrada (2)'!$G$5*'LANZ PP CAMBIOS'!I25+IFERROR(VLOOKUP($A$9,'Datos de Entrada (1)'!$A$7:$E$10,MATCH(I36,'Datos de Entrada (1)'!$A$6:$E$6,0),0),0) -> 0 | ... U37: ='Datos de Entrada (2)'!$G$5*'LANZ PP CAMBIOS'!U25+IFERROR(VLOOKUP($A$9,'Datos de Entrada (1)'!$A$7:$E$10,MATCH(U36,'Datos de Entrada (1)'!$A$6:$E$6,0),0),0) -> 0
A38: EXITS | B38: ='Datos de Entrada (1)'!$E$20 -> 20 | C38: =B38+B42-B37 -> 20 | D38: =C38+C42-C37 -> 20 | E38: =D38+D42-D37 -> 20 | F38: =E38+E42-E37 -> 20 | G38: =F38+F42-F37 -> 20 | H38: =G38+G42-G37 -> 20 | I38: =H38+H42-H37 -> 20 | J38: =I38+I42-I37 -> 20 | ... U38: =T38+T42-T37 -> 40
A39: NN | B39: =IF(B37=0,0,MAX(0,B37+'Datos de Entrada (1)'!$B$20-'LANZ PP'!B38)) -> 0 | C39: =IF(C37=0,0,MAX(0,C37+'Datos de Entrada (1)'!$B$20-'LANZ PP'!C38)) -> 0 | D39: =IF(D37=0,0,MAX(0,D37+'Datos de Entrada (1)'!$B$20-'LANZ PP'!D38)) -> 0 | E39: =IF(E37=0,0,MAX(0,E37+'Datos de Entrada (1)'!$B$20-'LANZ PP'!E38)) -> 0 | F39: =IF(F37=0,0,MAX(0,F37+'Datos de Entrada (1)'!$B$20-'LANZ PP'!F38)) -> 0 | G39: =IF(G37=0,0,MAX(0,G37+'Datos de Entrada (1)'!$B$20-'LANZ PP'!G38)) -> 0 | H39: =IF(H37=0,0,MAX(0,H37+'Datos de Entrada (1)'!$B$20-'LANZ PP'!H38)) -> 0 | I39: =IF(I37=0,0,MAX(0,I37+'Datos de Entrada (1)'!$B$20-'LANZ PP'!I38)) -> 0 | ... U39: =IF(U37=0,0,MAX(0,U37+'Datos de Entrada (1)'!$B$20-'LANZ PP'!U38)) -> 0
A40: AUXILIAR (NN, CON DEFECTOS) | B40: =ROUNDUP(B39/(1-('Datos de Entrada (1)'!$D$20/100)),0) -> 0 | C40: =ROUNDUP(C39/(1-('Datos de Entrada (1)'!$D$20/100)),0) -> 0 | D40: =ROUNDUP(D39/(1-('Datos de Entrada (1)'!$D$20/100)),0) -> 0 | E40: =ROUNDUP(E39/(1-('Datos de Entrada (1)'!$D$20/100)),0) -> 0 | F40: =ROUNDUP(F39/(1-('Datos de Entrada (1)'!$D$20/100)),0) -> 0 | G40: =ROUNDUP(G39/(1-('Datos de Entrada (1)'!$D$20/100)),0) -> 0 | H40: =ROUNDUP(H39/(1-('Datos de Entrada (1)'!$D$20/100)),0) -> 0 | I40: =ROUNDUP(I39/(1-('Datos de Entrada (1)'!$D$20/100)),0) -> 0 | ... U40: =ROUNDUP(U39/(1-('Datos de Entrada (1)'!$D$20/100)),0) -> 0
A41: RPP | B41: =ROUNDUP(B40/'Datos de Entrada (1)'!$F$20,0)*'Datos de Entrada (1)'!$F$20 -> 0 | C41: =ROUNDUP(C40/'Datos de Entrada (1)'!$F$20,0)*'Datos de Entrada (1)'!$F$20 -> 0 | D41: =ROUNDUP(D40/'Datos de Entrada (1)'!$F$20,0)*'Datos de Entrada (1)'!$F$20 -> 0 | E41: =ROUNDUP(E40/'Datos de Entrada (1)'!$F$20,0)*'Datos de Entrada (1)'!$F$20 -> 0 | F41: =ROUNDUP(F40/'Datos de Entrada (1)'!$F$20,0)*'Datos de Entrada (1)'!$F$20 -> 0 | G41: =ROUNDUP(G40/'Datos de Entrada (1)'!$F$20,0)*'Datos de Entrada (1)'!$F$20 -> 0 | H41: =ROUNDUP(H40/'Datos de Entrada (1)'!$F$20,0)*'Datos de Entrada (1)'!$F$20 -> 0 | I41: =ROUNDUP(I40/'Datos de Entrada (1)'!$F$20,0)*'Datos de Entrada (1)'!$F$20 -> 0 | ... U41: =ROUNDUP(U40/'Datos de Entrada (1)'!$F$20,0)*'Datos de Entrada (1)'!$F$20 -> 0
A42: AUXILIAR 3 (CORRECTAS) | B42: =ROUNDDOWN(B41*(1-('Datos de Entrada (1)'!$D$20/100)),0) -> 0 | C42: =ROUNDDOWN(C41*(1-('Datos de Entrada (1)'!$D$20/100)),0) -> 0 | D42: =ROUNDDOWN(D41*(1-('Datos de Entrada (1)'!$D$20/100)),0) -> 0 | E42: =ROUNDDOWN(E41*(1-('Datos de Entrada (1)'!$D$20/100)),0) -> 0 | F42: =ROUNDDOWN(F41*(1-('Datos de Entrada (1)'!$D$20/100)),0) -> 0 | G42: =ROUNDDOWN(G41*(1-('Datos de Entrada (1)'!$D$20/100)),0) -> 0 | H42: =ROUNDDOWN(H41*(1-('Datos de Entrada (1)'!$D$20/100)),0) -> 0 | I42: =ROUNDDOWN(I41*(1-('Datos de Entrada (1)'!$D$20/100)),0) -> 0 | ... U42: =ROUNDDOWN(U41*(1-('Datos de Entrada (1)'!$D$20/100)),0) -> 0
A43: LANZ PP (EN CUENTA DEF. Y LOTE) | B43: =OFFSET(B41,0,'Datos de Entrada (1)'!$C$20) -> 0 | C43: =OFFSET(C41,0,'Datos de Entrada (1)'!$C$20) -> 0 | D43: =OFFSET(D41,0,'Datos de Entrada (1)'!$C$20) -> 0 | E43: =OFFSET(E41,0,'Datos de Entrada (1)'!$C$20) -> 0 | F43: =OFFSET(F41,0,'Datos de Entrada (1)'!$C$20) -> 0 | G43: =OFFSET(G41,0,'Datos de Entrada (1)'!$C$20) -> 0 | H43: =OFFSET(H41,0,'Datos de Entrada (1)'!$C$20) -> 0 | I43: =OFFSET(I41,0,'Datos de Entrada (1)'!$C$20) -> 0 | ... U43: =OFFSET(U41,0,'Datos de Entrada (1)'!$C$20) -> 0
...
